Workbook

Sheet LEEME
B2: Río Negro — Lago Chapo | Perfiles de monitoreo extraídos de los DWG
B5: ORIGEN DE LOS DATOS
B6: Los DWG originales se convirtieron a DXF con LibreDWG (dwg2dxf 0.14), compilado
B7: desde el código fuente. Los perfiles se leyeron con la librería ezdxf.
B8: Archivos: '2014 01 Perfiles Monitoreo RNegro b.dwg' y '2018 11 Perfiles Monitoreo RNegro.dwg'.
B10: ESCALAS Y EXAGERACIÓN VERTICAL (importante)
B11: Los gráficos de perfil están dibujados con exageración vertical ×10:
B12: horizontal : 1 unidad de dibujo = 1 m
B13: vertical : 10 unidades de dibujo = 1 m
B14: La escala horizontal se verificó comparando el ancho del gráfico (625.9 u) con la
B15: longitud real de la traza del corte en planta (626 m, en coordenadas UTM).
B16: La escala vertical se calibró en cada gráfico con las etiquetas del eje de cotas;
... B51: Calibracion — evidencia de la calibración de escalas, auditable

Sheet Perfiles
A1: Plano | B1: Fecha | C1: Corte | D1: Punto | E1: Estacion_m | F1: Cota_msnm
A2: 2014-01 | B2: enero 2014 | C2: 1 | D2: 1 | E2: 0 | F2: 230.602
A3: 2014-01 | B3: enero 2014 | C3: 1 | D3: 2 | E3: 43.468 | F3: 232.557
A4: 2014-01 | B4: enero 2014 | C4: 1 | D4: 3 | E4: 61.808 | F4: 234.373
A5: 2014-01 | B5: enero 2014 | C5: 1 | D5: 4 | E5: 98.715 | F5: 237.492
A6: 2014-01 | B6: enero 2014 | C6: 1 | D6: 5 | E6: 119.332 | F6: 239.153
A7: 2014-01 | B7: enero 2014 | C7: 1 | D7: 6 | E7: 125.28 | F7: 239.716
A8: 2014-01 | B8: enero 2014 | C8: 1 | D8: 7 | E8: 169.379 | F8: 239.587
A9: 2014-01 | B9: enero 2014 | C9: 1 | D9: 8 | E9: 172.381 | F9: 239.548
A10: 2014-01 | B10: enero 2014 | C10: 1 | D10: 9 | E10: 176.531 | F10: 239.542
A11: 2014-01 | B11: enero 2014 | C11: 1 | D11: 10 | E11: 217.091 | F11: 239.922
A12: 2014-01 | B12: enero 2014 | C12: 1 | D12: 11 | E12: 237.287 | F12: 227.242
A13: 2014-01 | B13: enero 2014 | C13: 1 | D13: 12 | E13: 239.522 | F13: 226.007
... A453: 2018-11 | B453: junio 2018 | C453: C | D453: 22 | E453: 288.377 | F453: 248.572

Sheet Perfil_1
A1: CORTE 1 — sección transversal (geometría de referencia)
A2: Idéntica en los planos de 2014 y 2018. Cotas en m.s.n.m., estación en m desde el extremo izquierdo del gráfico.
A4: Estacion_m | B4: Cota_msnm
A5: 0 | B5: 230.602
A6: 43.468 | B6: 232.557
A7: 61.808 | B7: 234.373
A8: 98.715 | B8: 237.492
A9: 119.332 | B9: 239.153
A10: 125.28 | B10: 239.716
A11: 169.379 | B11: 239.587
A12: 172.381 | B12: 239.548
A13: 176.531 | B13: 239.542
A14: 217.091 | B14: 239.922
A15: 237.287 | B15: 227.242
A16: 239.522 | B16: 226.007
... A36: 625.94 | B36: 236.538
A38: Capacidad a niveles del lago
A39: Nivel_msnm | B39: Referencia | C39: Area_mojada_m2 | D39: Ancho_m
A40: 230 | B40: minimo historico citado | C40: 349.73 | D40: 131.1
A41: 231 | B41: cota minima provisional 3TA | C41: 504.41 | D41: 186.74
A42: 243 | B42: maximo normal aproximado | C42: 5773.81 | D42: 625.94

Sheet Perfil_2
A1: CORTE 2 — sección transversal (geometría de referencia)
A2: Idéntica en los planos de 2014 y 2018. Cotas en m.s.n.m., estación en m desde el extremo izquierdo del gráfico.
A4: Estacion_m | B4: Cota_msnm
A5: 0 | B5: 242.912
A6: 5.761 | B6: 242.802
A7: 41.048 | B7: 243.058
A8: 49.825 | B8: 243.052
A9: 81.751 | B9: 243.003
A10: 93.726 | B10: 242.999
A11: 102.683 | B11: 243.229
A12: 111.618 | B12: 243.256
A13: 127.593 | B13: 243.354
A14: 144.763 | B14: 243.5
A15: 151.981 | B15: 243.509
A16: 170.522 | B16: 243.448
... A35: 382.947 | B35: 243.187
A37: Capacidad a niveles del lago
A38: Nivel_msnm | B38: Referencia | C38: Area_mojada_m2 | D38: Ancho_m
A39: 230 | B39: minimo historico citado | C39: 0 | D39: 0
A40: 231 | B40: cota minima provisional 3TA | C40: 0 | D40: 0
A41: 243 | B41: maximo normal aproximado | C41: 1056.55 | D41: 170.74

Sheet Perfil_3
A1: CORTE 3 — sección transversal (geometría de referencia)
A2: Idéntica en los planos de 2014 y 2018. Cotas en m.s.n.m., estación en m desde el extremo izquierdo del gráfico.
A4: Estacion_m | B4: Cota_msnm
A5: 0 | B5: 243.829
A6: 37.381 | B6: 243.943
A7: 44.866 | B7: 243.929
A8: 58.08 | B8: 244.039
A9: 62.136 | B9: 244.066
A10: 68.384 | B10: 244.172
A11: 80.508 | B11: 237.455
A12: 80.713 | B12: 237.364
A13: 80.795 | B13: 237.362
A14: 93.669 | B14: 235.386
A15: 101.793 | B15: 235.347
A16: 103.237 | B16: 235.345
... A43: 436.343 | B43: 245.239
A45: Capacidad a niveles del lago
A46: Nivel_msnm | B46: Referencia | C46: Area_mojada_m2 | D46: Ancho_m
A47: 230 | B47: minimo historico citado | C47: 0 | D47: 0
A48: 231 | B48: cota minima provisional 3TA | C48: 0 | D48: 0
A49: 243 | B49: maximo normal aproximado | C49: 1916.21 | D49: 327.29

Sheet Perfil_4
A1: CORTE 4 — sección transversal (geometría de referencia)
A2: Idéntica en los planos de 2014 y 2018. Cotas en m.s.n.m., estación en m desde el extremo izquierdo del gráfico.
A4: Estacion_m | B4: Cota_msnm
A5: 0 | B5: 246.529
A6: 15.423 | B6: 246.476
A7: 16.735 | B7: 246.471
A8: 31.231 | B8: 246.356
A9: 48.293 | B9: 246.242
A10: 53.266 | B10: 243.723
A11: 58.807 | B11: 239.81
A12: 72.897 | B12: 239.93
A13: 76.118 | B13: 239.9
A14: 77.251 | B14: 239.886
A15: 77.854 | B15: 240.409
A16: 90.662 | B16: 242.377
... A26: 205.055 | B26: 245.963
A28: Capacidad a niveles del lago
A29: Nivel_msnm | B29: Referencia | C29: Area_mojada_m2 | D29: Ancho_m
A30: 230 | B30: minimo historico citado | C30: 0 | D30: 0
A31: 231 | B31: cota minima provisional 3TA | C31: 0 | D31: 0
A32: 243 | B32: maximo normal aproximado | C32: 121.23 | D32: 88.43

Sheet Perfil_A
A1: CORTE A — sección transversal (geometría de referencia)
A2: Idéntica en los planos de 2014 y 2018. Cotas en m.s.n.m., estación en m desde el extremo izquierdo del gráfico.
A4: Estacion_m | B4: Cota_msnm
A5: 0 | B5: 233.304
A6: 48.177 | B6: 234.155
A7: 71.024 | B7: 234.915
A8: 107.894 | B8: 236.443
A9: 152.756 | B9: 238.167
A10: 165.168 | B10: 238.75
A11: 175.995 | B11: 238.812
A12: 207.495 | B12: 239.109
A13: 224.654 | B13: 239.322
A14: 289.787 | B14: 240.489
A15: 300.497 | B15: 240.613
A16: 305.952 | B16: 240.628
... A41: 841.626 | B41: 240.514
A43: Capacidad a niveles del lago
A44: Nivel_msnm | B44: Referencia | C44: Area_mojada_m2 | D44: Ancho_m
A45: 230 | B45: minimo historico citado | C45: 155.38 | D45: 90.88
A46: 231 | B46: cota minima provisional 3TA | C46: 263.99 | D46: 159.58
A47: 243 | B47: maximo normal aproximado | C47: 5742.82 | D47: 841.63

Sheet Perfil_B
A1: CORTE B — sección transversal (geometría de referencia)
A2: Idéntica en los planos de 2014 y 2018. Cotas en m.s.n.m., estación en m desde el extremo izquierdo del gráfico.
A4: Estacion_m | B4: Cota_msnm
A5: 0 | B5: 243.497
A6: 48.775 | B6: 243.294
A7: 49.081 | B7: 243.289
A8: 50.161 | B8: 242.741
A9: 62.166 | B9: 237.147
A10: 77.28 | B10: 237.14
A11: 109.524 | B11: 236.875
A12: 115.293 | B12: 235.108
A13: 115.742 | B13: 234.985
A14: 116.743 | B14: 234.98
A15: 134 | B15: 234.884
A16: 158.32 | B16: 237.725
... A47: 439.725 | B47: 245.269
A49: Capacidad a niveles del lago
A50: Nivel_msnm | B50: Referencia | C50: Area_mojada_m2 | D50: Ancho_m
A51: 230 | B51: minimo historico citado | C51: 0 | D51: 0
A52: 231 | B52: cota minima provisional 3TA | C52: 0 | D52: 0
A53: 243 | B53: maximo normal aproximado | C53: 1889.87 | D53: 299.47

Sheet Perfil_C
A1: CORTE C — sección transversal (geometría de referencia)
A2: Idéntica en los planos de 2014 y 2018. Cotas en m.s.n.m., estación en m desde el extremo izquierdo del gráfico.
A4: Estacion_m | B4: Cota_msnm
A5: 0 | B5: 249.175
A6: 44.631 | B6: 249.106
A7: 45.236 | B7: 249.076
A8: 49.091 | B8: 249.048
A9: 58.176 | B9: 246.078
A10: 64.926 | B10: 244.262
A11: 71.552 | B11: 244.461
A12: 93.546 | B12: 244.307
A13: 99.218 | B13: 243.63
A14: 102.243 | B14: 243.616
A15: 111.854 | B15: 243.972
A16: 121.44 | B16: 245.422
... A26: 288.377 | B26: 248.572
A28: Capacidad a niveles del lago
A29: Nivel_msnm | B29: Referencia | C29: Area_mojada_m2 | D29: Ancho_m
A30: 230 | B30: minimo historico citado | C30: 0 | D30: 0
A31: 231 | B31: cota minima provisional 3TA | C31: 0 | D31: 0
A32: 243 | B32: maximo normal aproximado | C32: 0 | D32: 0

Sheet Geometria_cortes
A1: Resumen morfométrico de las 7 secciones
A3: Corte | B3: N_puntos | C3: Ancho_levantado_m | D3: Cota_min_msnm | E3: Cota_max_msnm | F3: Relieve_m | G3: Estacion_thalweg_m | H3: Area_230_m2 | I3: Ancho_230_m | J3: Area_231_m2 | K3: Ancho_231_m | L3: Area_243_m2 | M3: Ancho_243_m
A4: 1 | B4: 32 | C4: 625.94 | D4: 225.69 | E4: 239.92 | F4: 14.23 | G4: 262.41 | H4: 349.73 | I4: 131.1 | J4: 504.41 | K4: 186.74 | L4: 5773.81 | M4: 625.94
A5: 2 | B5: 31 | C5: 382.95 | D5: 231.35 | E5: 243.83 | F5: 12.48 | G5: 281.28 | H5: 0 | I5: 0 | J5: 0 | K5: 0 | L5: 1056.55 | M5: 170.74
A6: 3 | B6: 39 | C6: 436.34 | D6: 235.06 | E6: 245.24 | F6: 10.18 | G6: 381.57 | H6: 0 | I6: 0 | J6: 0 | K6: 0 | L6: 1916.21 | M6: 327.29
A7: 4 | B7: 22 | C7: 205.06 | D7: 239.81 | E7: 246.53 | F7: 6.72 | G7: 58.81 | H7: 0 | I7: 0 | J7: 0 | K7: 0 | L7: 121.23 | M7: 88.43
A8: A | B8: 37 | C8: 841.63 | D8: 227.21 | E8: 241.57 | F8: 14.36 | G8: 355.97 | H8: 155.38 | I8: 90.88 | J8: 263.99 | K8: 159.58 | L8: 5742.82 | M8: 841.63
A9: B | B9: 43 | C9: 439.73 | D9: 232.62 | E9: 245.27 | F9: 12.65 | G9: 358.91 | H9: 0 | I9: 0 | J9: 0 | K9: 0 | L9: 1889.87 | M9: 299.47
A10: C | B10: 22 | C10: 288.38 | D10: 243.62 | E10: 249.18 | F10: 5.56 | G10: 102.24 | H10: 0 | I10: 0 | J10: 0 | K10: 0 | L10: 0 | M10: 0
A13: El thalweg es el punto más bajo del perfil. Area/Ancho son la sección mojada si el agua alcanzara esa cota.

Sheet Poligonos_erosion
A1: Polígonos dibujados sobre los perfiles (inventario auditable)
A2: Área ya corregida por la exageración vertical ×10. La columna 'Capa' permite auditar el origen: los de capa 'texto' son probablemente anotaciones.
A4: Plano | B4: Fecha | C4: Corte | D4: Capa | E4: Tipo | F4: N_vert | G4: Area_real_m2 | H4: Est_ini_m | I4: Est_fin_m | J4: Ancho_m | K4: Cota_min | L4: Cota_max | M4: Alto_m | N4: Probable_anotacion
A5: 2014-01 | B5: enero 2014 | C5: 1 | D5: 0 | E5: HATCH+LWPOLYLINE | F5: 94 | G5: 1246.04 | H5: 132.41 | I5: 239.51 | J5: 107.11 | K5: 225.95 | L5: 239.92 | M5: 13.97
A6: 2014-01 | B6: enero 2014 | C6: 1 | D6: 0 | E6: HATCH | F6: 36 | G6: 326.03 | H6: 102.38 | I6: 140.51 | J6: 38.13 | K6: 226.28 | L6: 239.72 | M6: 13.44
A7: 2014-01 | B7: enero 2014 | C7: 1 | D7: 0 | E7: HATCH | F7: 16 | G7: 247.73 | H7: 81.42 | I7: 114.99 | J7: 33.57 | K7: 226.57 | L7: 237.79 | M7: 11.21
A8: 2014-01 | B8: enero 2014 | C8: 1 | D8: texto | E8: HATCH | F8: 14 | G8: 72.73 | H8: 65.08 | I8: 89.17 | J8: 24.1 | K8: 226.64 | L8: 236.03 | M8: 9.4 | N8: SI
A9: 2014-01 | B9: enero 2014 | C9: 1 | D9: 0 | E9: HATCH | F9: 30 | G9: 72.14 | H9: 58.62 | I9: 83.63 | J9: 25.01 | K9: 226.67 | L9: 234.65 | M9: 7.98
A10: 2014-01 | B10: enero 2014 | C10: 1 | D10: 0 | E10: HATCH+LWPOLYLINE | F10: 10 | G10: 32.51 | H10: 128.29 | I10: 140.51 | J10: 12.23 | K10: 226.28 | L10: 239.71 | M10: 13.43
A11: 2014-01 | B11: enero 2014 | C11: 1 | D11: 0 | E11: HATCH | F11: 4 | G11: 0.19 | H11: 140 | I11: 140.51 | J11: 0.51 | K11: 226.28 | L11: 227.12 | M11: 0.84
A12: 2014-01 | B12: enero 2014 | C12: 2 | D12: 0 | E12: HATCH | F12: 46 | G12: 689.36 | H12: 115.64 | I12: 193.28 | J12: 77.64 | K12: 231.58 | L12: 243.51 | M12: 11.93
A13: 2014-01 | B13: enero 2014 | C13: 2 | D13: 0 | E13: LWPOLYLINE | F13: 12 | G13: 314.2 | H13: 122.03 | I13: 193.28 | J13: 71.25 | K13: 231.58 | L13: 236.73 | M13: 5.15
A14: 2014-01 | B14: enero 2014 | C14: 2 | D14: 0 | E14: HATCH+LWPOLYLINE | F14: 10 | G14: 74.15 | H14: 162.62 | I14: 233.94 | J14: 71.32 | K14: 231.58 | L14: 236.8 | M14: 5.22
A15: 2014-01 | B15: enero 2014 | C15: 2 | D15: 0 | E15: LWPOLYLINE | F15: 4 | G15: 1.8 | H15: 116.32 | I15: 122.03 | J15: 5.7 | K15: 236.73 | L15: 243.29 | M15: 6.55
A16: 2014-01 | B16: enero 2014 | C16: 3 | D16: 0 | E16: HATCH | F16: 44 | G16: 417.08 | H16: 10.34 | I16: 80.71 | J16: 70.37 | K16: 237.09 | L16: 244.17 | M16: 7.08
A17: 2014-01 | B17: enero 2014 | C17: 3 | D17: 0 | E17: HATCH+LWPOLYLINE | F17: 20 | G17: 96.52 | H17: 16.68 | I17: 93.67 | J17: 76.99 | K17: 235.39 | L17: 237.36 | M17: 1.98
A18: 2014-01 | B18: enero 2014 | C18: 3 | D18: 0 | E18: HATCH+LWPOLYLINE | F18: 16 | G18: 10.3 | H18: 0 | I18: 22.13 | J18: 22.13 | K18: 236.25 | L18: 243.86 | M18: 7.62
A19: 2014-01 | B19: enero 2014 | C19: 3 | D19: 0 | E19: LWPOLYLINE | F19: 5 | G19: 1.91 | H19: 11.13 | I19: 16.68 | J19: 5.54 | K19: 237.16 | L19: 243.86 | M19: 6.7
A20: 2014-01 | B20: enero 2014 | C20: 4 | D20: 0 | E20: HATCH | F20: 14 | G20: 98.35 | H20: 23.32 | I20: 47.48 | J20: 24.16 | K20: 239.77 | L20: 246.36 | M20: 6.58
... A27: 2014-01 | B27: enero 2014 | C27: A | D27: 0 | E27: HATCH | F27: 30 | G27: 26.3 | H27: 266.89 | I27: 282.99 | J27: 16.1 | K27: 228.25 | L27: 240.14 | M27: 11.89
A28: 2014-01 | B28: enero 2014 | C28: A | D28: texto | E28: HATCH | F28: 12 | G28: 23.87 | H28: 270.44 | I28: 281.19 | J28: 10.74 | K28: 231.2 | L28: 240.22 | M28: 9.02 | N28: SI
A29: 2014-01 | B29: enero 2014 | C29: A | D29: 0 | E29: HATCH+LWPOLYLINE | F29: 11 | G29: 14.27 | H29: 288.92 | I29: 298.57 | J29: 9.65 | K29: 227.08 | L29: 240.51 | M29: 13.42
A30: 2014-01 | B30: enero 2014 | C30: A | D30: 0 | E30: HATCH | F30: 12 | G30: 9.17 | H30: 264.3 | I30: 276.34 | J30: 12.03 | K30: 233.12 | L30: 240.08 | M30: 6.96
A31: 2014-01 | B31: enero 2014 | C31: B | D31: 0 | E31: HATCH+LWPOLYLINE | F31: 7 | G31: 66.08 | H31: 324.25 | I31: 357.99 | J31: 33.74 | K31: 232.54 | L31: 238.35 | M31: 5.81
A32: 2018-11 | B32: junio 2018 | C32: 1 | D32: 0 | E32: HATCH | F32: 94 | G32: 1246.04 | H32: 132.41 | I32: 239.51 | J32: 107.11 | K32: 225.95 | L32: 239.92 | M32: 13.97
A33: 2018-11 | B33: junio 2018 | C33: 1 | D33: 0 | E33: HATCH | F33: 36 | G33: 326.03 | H33: 102.38 | I33: 140.51 | J33: 38.13 | K33: 226.28 | L33: 239.72 | M33: 13.44
A34: 2018-11 | B34: junio 2018 | C34: 1 | D34: 0 | E34: HATCH | F34: 16 | G34: 247.73 | H34: 81.42 | I34: 114.99 | J34: 33.57 | K34: 226.57 | L34: 237.79 | M34: 11.21
A35: 2018-11 | B35: junio 2018 | C35: 1 | D35: texto | E35: HATCH | F35: 14 | G35: 72.73 | H35: 65.08 | I35: 89.17 | J35: 24.1 | K35: 226.64 | L35: 236.03 | M35: 9.4 | N35: SI
A36: 2018-11 | B36: junio 2018 | C36: 1 | D36: 0 | E36: HATCH | F36: 30 | G36: 72.14 | H36: 58.62 | I36: 83.63 | J36: 25.01 | K36: 226.67 | L36: 234.65 | M36: 7.98
A37: 2018-11 | B37: junio 2018 | C37: 1 | D37: 0 | E37: HATCH | F37: 25 | G37: 32.31 | H37: 128.29 | I37: 140 | J37: 11.71 | K37: 226.45 | L37: 239.71 | M37: 13.26
A38: 2018-11 | B38: junio 2018 | C38: 1 | D38: 0 | E38: HATCH | F38: 4 | G38: 0.19 | H38: 140 | I38: 140.51 | J38: 0.51 | K38: 226.28 | L38: 227.12 | M38: 0.84
A39: 2018-11 | B39: junio 2018 | C39: 2 | D39: 0 | E39: HATCH | F39: 46 | G39: 689.36 | H39: 115.64 | I39: 193.28 | J39: 77.64 | K39: 231.58 | L39: 243.51 | M39: 11.93
A40: 2018-11 | B40: junio 2018 | C40: 2 | D40: 0 | E40: HATCH | F40: 20 | G40: 74.14 | H40: 162.62 | I40: 233.94 | J40: 71.32 | K40: 231.58 | L40: 236.8 | M40: 5.22
A41: 2018-11 | B41: junio 2018 | C41: 3 | D41: 0 | E41: HATCH | F41: 44 | G41: 417.08 | H41: 10.34 | I41: 80.71 | J41: 70.37 | K41: 237.09 | L41: 244.17 | M41: 7.08
A42: 2018-11 | B42: junio 2018 | C42: 3 | D42: 0 | E42: HATCH | F42: 20 | G42: 96.52 | H42: 16.68 | I42: 93.67 | J42: 76.99 | K42: 235.39 | L42: 237.36 | M42: 1.98
A43: 2018-11 | B43: junio 2018 | C43: 3 | D43: 0 | E43: HATCH | F43: 32 | G43: 10.3 | H43: 0 | I43: 22.13 | J43: 22.13 | K43: 236.25 | L43: 243.86 | M43: 7.62
A44: 2018-11 | B44: junio 2018 | C44: 4 | D44: 0 | E44: HATCH | F44: 34 | G44: 333.18 | H44: 3.08 | I44: 77.25 | J44: 74.17 | K44: 235.24 | L44: 246.52 | M44: 11.28
A45: 2018-11 | B45: junio 2018 | C45: 4 | D45: 0 | E45: HATCH | F45: 14 | G45: 98.35 | H45: 31.23 | I45: 55.39 | J45: 24.16 | K45: 239.77 | L45: 246.36 | M45: 6.58
A46: 2018-11 | B46: junio 2018 | C46: 4 | D46: 0 | E46: HATCH | F46: 28 | G46: 79.91 | H46: -2.21 | I46: 15.6 | J46: 17.81 | K46: 235.55 | L46: 246.54 | M46: 10.99
A47: 2018-11 | B47: junio 2018 | C47: 4 | D47: 0 | E47: HATCH | F47: 28 | G47: 55.15 | H47: 21.04 | I47: 34.93 | J47: 13.89 | K47: 239.64 | L47: 246.44 | M47: 6.79
...

Sheet Resumen_erosion
A1: Área de los polígonos dibujados, por corte y plano
A2: NO INTERPRETAR COMO EROSIÓN POR PERÍODO: las diferencias son nulas en 4 de los 7 cortes, lo que indica ediciones del dibujo y no una medición entre fechas.
A3: Excluye los polígonos de la capa 'texto' (probables anotaciones). Ver hoja 'Hallazgos', punto 4.
A4: Corte | B4: Area_2014_m2 | C4: N_pol_2014 | D4: Area_2018_m2 | E4: N_pol_2018 | F4: Diferencia_m2
A5: 1 | B5: 1924.64 | C5: 6 | D5: 1924.45 | E5: 6 | F5: -0.2
A6: 2 | B6: 1079.51 | C6: 4 | D6: 763.51 | E6: 2 | F6: -316
A7: 3 | B7: 525.81 | C7: 4 | D7: 523.9 | E7: 3 | F7: -1.91
A8: 4 | B8: 153.08 | C8: 4 | D8: 621.32 | E8: 7 | F8: 468.24
A9: A | B9: 482.27 | C9: 6 | D9: 543.6 | E9: 11 | F9: 61.33
A10: B | B10: 66.08 | C10: 1 | D10: 66.08 | E10: 1 | F10: 0
A11: C | B11: 0 | C11: 0 | D11: 0 | E11: 0 | F11: 0
A12: TOTAL | B12: =SUM(B5:B11) | D12: =SUM(D5:D11) | F12: =SUM(F5:F11)

Sheet Volumenes
A1: Volúmenes por el método de áreas medias — PLANTILLA
A2: La columna C viene precargada con la distancia RECTA entre los puntos medios de las trazas UTM. Reemplácela por la distancia medida a lo largo del eje del cauce, que es siempre mayor. Las demás columnas se calculan solas.
A3: Los cortes están ordenados de aguas abajo hacia aguas arriba según la cota de su thalweg. Confirme este orden con las progresivas reales antes de usarlo.
A4: ATENCIÓN: las áreas que toma esta hoja provienen de 'Resumen_erosion', cuya validez como erosión por período NO está confirmada (ver hoja Hallazgos).
A6: Corte_A | B6: Corte_B | C6: Distancia_m (INGRESAR) | D6: Area_A_m2 | E6: Area_B_m2 | F6: Area_media_m2 | G6: Volumen_m3
A7: 1 | B7: A | C7: 154.3 | D7: =IFERROR(VLOOKUP(A7,Resumen_erosion!$A$5:$D$11,4,FALSE),"") | E7: =IFERROR(VLOOKUP(B7,Resumen_erosion!$A$5:$D$11,4,FALSE),"") | F7: =IFERROR((D7+E7)/2,"") | G7: =IFERROR(F7*C7,"")
A8: A | B8: 2 | C8: 508 | D8: =IFERROR(VLOOKUP(A8,Resumen_erosion!$A$5:$D$11,4,FALSE),"") | E8: =IFERROR(VLOOKUP(B8,Resumen_erosion!$A$5:$D$11,4,FALSE),"") | F8: =IFERROR((D8+E8)/2,"") | G8: =IFERROR(F8*C8,"")
A9: 2 | B9: B | C9: 128.9 | D9: =IFERROR(VLOOKUP(A9,Resumen_erosion!$A$5:$D$11,4,FALSE),"") | E9: =IFERROR(VLOOKUP(B9,Resumen_erosion!$A$5:$D$11,4,FALSE),"") | F9: =IFERROR((D9+E9)/2,"") | G9: =IFERROR(F9*C9,"")
A10: B | B10: 3 | C10: 117 | D10: =IFERROR(VLOOKUP(A10,Resumen_erosion!$A$5:$D$11,4,FALSE),"") | E10: =IFERROR(VLOOKUP(B10,Resumen_erosion!$A$5:$D$11,4,FALSE),"") | F10: =IFERROR((D10+E10)/2,"") | G10: =IFERROR(F10*C10,"")
A11: 3 | B11: 4 | C11: 283.7 | D11: =IFERROR(VLOOKUP(A11,Resumen_erosion!$A$5:$D$11,4,FALSE),"") | E11: =IFERROR(VLOOKUP(B11,Resumen_erosion!$A$5:$D$11,4,FALSE),"") | F11: =IFERROR((D11+E11)/2,"") | G11: =IFERROR(F11*C11,"")
A12: 4 | B12: C | C12: 399.5 | D12: =IFERROR(VLOOKUP(A12,Resumen_erosion!$A$5:$D$11,4,FALSE),"") | E12: =IFERROR(VLOOKUP(B12,Resumen_erosion!$A$5:$D$11,4,FALSE),"") | F12: =IFERROR((D12+E12)/2,"") | G12: =IFERROR(F12*C12,"")
F13: TOTAL m³ | G13: =SUM(G7:G12)

Sheet Progresivas
A1: Ubicación de los cortes en planta (coordenadas UTM)
A2: Extraída de la capa 'corte' de los DWG. Cada corte se identifica por sus dos rótulos de extremo; el punto medio se usa para medir distancias entre cortes.
A4: Orden | B4: Corte | C4: Thalweg_msnm | D4: X_ini | E4: Y_ini | F4: X_fin | G4: Y_fin | H4: X_medio | I4: Y_medio | J4: Largo_traza_m | K4: Dist_al_siguiente_m | L4: Progresiva_acum_m
A5: 1 | B5: 1 | C5: 225.69 | D5: 709075.12 | E5: 5412052.4 | F5: 709408.41 | G5: 5411569.4 | H5: 709241.76 | I5: 5411810.9 | J5: 586.8 | K5: 154.3 | L5: 0
A6: 2 | B6: A | C6: 227.21 | D6: 709129.04 | E6: 5412262.4 | F6: 709562.64 | G6: 5411587.1 | H6: 709345.84 | I6: 5411924.8 | J6: 802.5 | K6: 508 | L6: 154.3
A7: 3 | B7: 2 | C7: 231.35 | D7: 709768.58 | E7: 5412092.5 | F7: 709938.45 | G7: 5411793.6 | H7: 709853.52 | I7: 5411943.1 | J7: 343.8 | K7: 128.9 | L7: 662.3
A8: 4 | B8: B | C8: 232.62 | D8: 710050.29 | E8: 5411863 | F8: 709840.23 | G8: 5412204.2 | H8: 709945.26 | I8: 5412033.6 | J8: 400.6 | K8: 117 | L8: 791.2
A9: 5 | B9: 3 | C9: 235.06 | D9: 709907.56 | E9: 5412287.2 | F9: 710179.18 | G9: 5411907.5 | H9: 710043.37 | I9: 5412097.3 | J9: 466.9 | K9: 283.7 | L9: 908.2
A10: 6 | B10: 4 | C10: 239.81 | D10: 710256.16 | E10: 5412315.1 | F10: 710385.74 | G10: 5411996.9 | H10: 710320.95 | I10: 5412156 | J10: 343.6 | K10: 399.5 | L10: 1191.9
A11: 7 | B11: C | C11: 243.62 | D11: 710373.23 | E11: 5412610.2 | F11: 710528.49 | G11: 5412457.3 | H11: 710450.86 | I11: 5412533.8 | J11: 217.9 | L11: 1591.4
A13: Orden 1 = aguas abajo (desembocadura en el lago), deducido de la cota del thalweg. La progresión espacial de las coordenadas UTM es coherente con ese orden, lo que lo corrobora de forma independiente.
A14: Las distancias son en línea recta entre puntos medios. La distancia real a lo largo del cauce es mayor; úsela para los volúmenes definitivos.

Sheet Hallazgos
B2: Hallazgos derivados de los datos extraídos
B5: 1. ORDEN LONGITUDINAL DE LOS CORTES (deducido, no leído del plano)
B6: Ordenando por la cota del thalweg resulta, de aguas abajo a aguas arriba:
B7: 1 (225.69) -> A (227.21) -> 2 (231.35) -> B (232.62) -> 3 (235.06) -> 4 (239.81) -> C (243.62)
B8: El agua corre cuesta abajo, luego el corte con el fondo más bajo es el más cercano a
B9: la desembocadura en el lago. Este orden debe confirmarse contra las progresivas reales,
B10: pero es consistente y permite ordenar el análisis longitudinal.
B12: 2. SOLO DOS CORTES TIENEN EL LECHO BAJO EL NIVEL MÍNIMO DEL LAGO
B13: Cortes con thalweg bajo la cota 230 m.s.n.m.: 1, A.
B14: Son los dos cortes más cercanos a la desembocadura. El resto tiene el fondo por encima
B15: de 231 m.s.n.m., la cota mínima provisional ordenada por el Tercer Tribunal Ambiental.
B16: Lectura: son precisamente los cortes situados en la zona de influencia del abatimiento
... B47: columna de distancias de la hoja 'Volumenes' sin necesidad de trabajo de campo.

Sheet Calibracion
A1: Evidencia de calibración de escalas (auditable)
A2: La escala vertical se ajustó por mínimos cuadrados sobre las etiquetas del eje de cotas de cada gráfico. Un valor cercano a 10.00 u/m confirma la exageración ×10.
A4: Plano | B4: Corte | C4: Escala_V_u_por_m | D4: N_etiquetas_eje | E4: Residuo_max_u | F4: Residuo_max_m | G4: Escala_H_u_por_m | H4: Exageracion_vertical
A5: 2014-01 | B5: 1 | C5: 10.0548 | D5: 5 | E5: 0.438 | F5: 0.0436 | G5: 1 | H5: 10.05
A6: 2014-01 | B6: 2 | C6: 9.9716 | D6: 5 | E6: 0.228 | F6: 0.0228 | G6: 1 | H6: 9.97
A7: 2014-01 | B7: 3 | C7: 10.0107 | D7: 4 | E7: 0.057 | F7: 0.0057 | G7: 1 | H7: 10.01
A8: 2014-01 | B8: 4 | C8: 9.991 | D8: 3 | E8: 0.027 | F8: 0.0027 | G8: 1 | H8: 9.99
A9: 2014-01 | B9: A | C9: 10.0284 | D9: 5 | E9: 0.227 | F9: 0.0227 | G9: 1 | H9: 10.03
A10: 2014-01 | B10: B | C10: 9.9855 | D10: 5 | E10: 0.116 | F10: 0.0116 | G10: 1 | H10: 9.99
A11: 2014-01 | B11: C | C11: 9.9514 | D11: 2 | E11: 0 | F11: 0 | G11: 1 | H11: 9.95
A12: 2018-11 | B12: 1 | C12: 10.0548 | D12: 5 | E12: 0.438 | F12: 0.0436 | G12: 1 | H12: 10.05
A13: 2018-11 | B13: 2 | C13: 9.9716 | D13: 5 | E13: 0.228 | F13: 0.0228 | G13: 1 | H13: 9.97
A14: 2018-11 | B14: 3 | C14: 10.0107 | D14: 4 | E14: 0.057 | F14: 0.0057 | G14: 1 | H14: 10.01
A15: 2018-11 | B15: 4 | C15: 9.991 | D15: 3 | E15: 0.027 | F15: 0.0027 | G15: 1 | H15: 9.99
A16: 2018-11 | B16: A | C16: 10.0284 | D16: 5 | E16: 0.227 | F16: 0.0227 | G16: 1 | H16: 10.03
... A18: 2018-11 | B18: C | C18: 9.9514 | D18: 2 | E18: 0 | F18: 0 | G18: 1 | H18: 9.95
A20: Escala horizontal verificada de forma independiente: el gráfico del corte 1 mide 625.9 u de ancho y la traza del corte en planta mide 626 m en UTM.
